{"trial_id": "0000", "hyperparameters": {"space": [{"class_name": "Int", "config": {"name": "units1", "default": null, "conditions": [], "min_value": 32, "max_value": 128, "step": 32, "sampling": "linear"}}, {"class_name": "Int", "config": {"name": "units2", "default": null, "conditions": [], "min_value": 16, "max_value": 64, "step": 16, "sampling": "linear"}}, {"class_name": "Float", "config": {"name": "learning_rate", "default": 0.0001, "conditions": [], "min_value": 0.0001, "max_value": 0.01, "step": null, "sampling": "log"}}], "values": {"units1": 96, "units2": 48, "learning_rate": 0.0006177020005809435, "tuner/epochs": 2, "tuner/initial_epoch": 0, "tuner/bracket": 3, "tuner/round": 0}}, "metrics": {"metrics": {}}, "score": null, "best_step": 0, "status": "FAILED", "message": "Traceback (most recent call last):\n  File \"C:\\Users\\user\\anaconda3\\envs\\tf-2\\lib\\site-packages\\keras_tuner\\src\\engine\\base_tuner.py\", line 274, in _try_run_and_update_trial\n    self._run_and_update_trial(trial, *fit_args, **fit_kwargs)\n  File \"C:\\Users\\user\\anaconda3\\envs\\tf-2\\lib\\site-packages\\keras_tuner\\src\\engine\\base_tuner.py\", line 239, in _run_and_update_trial\n    results = self.run_trial(trial, *fit_args, **fit_kwargs)\n  File \"C:\\Users\\user\\anaconda3\\envs\\tf-2\\lib\\site-packages\\keras_tuner\\src\\tuners\\hyperband.py\", line 427, in run_trial\n    return super().run_trial(trial, *fit_args, **fit_kwargs)\n  File \"C:\\Users\\user\\anaconda3\\envs\\tf-2\\lib\\site-packages\\keras_tuner\\src\\engine\\tuner.py\", line 314, in run_trial\n    obj_value = self._build_and_fit_model(trial, *args, **copied_kwargs)\n  File \"C:\\Users\\user\\anaconda3\\envs\\tf-2\\lib\\site-packages\\keras_tuner\\src\\engine\\tuner.py\", line 233, in _build_and_fit_model\n    results = self.hypermodel.fit(hp, model, *args, **kwargs)\n  File \"C:\\Users\\user\\anaconda3\\envs\\tf-2\\lib\\site-packages\\keras_tuner\\src\\engine\\hypermodel.py\", line 149, in fit\n    return model.fit(*args, **kwargs)\n  File \"C:\\Users\\user\\anaconda3\\envs\\tf-2\\lib\\site-packages\\keras\\utils\\traceback_utils.py\", line 70, in error_handler\n    raise e.with_traceback(filtered_tb) from None\n  File \"C:\\Users\\user\\anaconda3\\envs\\tf-2\\lib\\site-packages\\keras\\utils\\traceback_utils.py\", line 65, in error_handler\n    return fn(*args, **kwargs)\nTypeError: Model.fit() got an unexpected keyword argument 'validation_spit'\n"}